Workbook

Sheet Resumen
A1: Mantenimiento preventivo semestral — flota Sunny
A2: Cronograma para 48 casas (excluye Piloto Promigas y Piloto HUAWEI) · datos de Metrum al 15-oct-2026
A4: Casas en alcance | D4: =COUNTA(Cronograma!E6:E53) -> 48
A5: Vencidas hoy (sin mantenimiento a tiempo) | D5: =COUNTIF(Cronograma!P6:P53,"Vencido") -> 4
A6: Vencen en ≤ 30 días | D6: =COUNTIF(Cronograma!P6:P53,"En ventana") -> 24
A7: Al día | D7: =COUNTIF(Cronograma!P6:P53,"Al día") -> 20
A8: Primera visita programada | D8: =MIN(Cronograma!N6:N53) -> 46314
A9: Última visita del primer ciclo | D9: =MAX(Cronograma!N6:N53) -> 46461
A11: Campañas del primer ciclo
A12: Cuadrilla | B12: Campaña | C12: Inicio | D12: Fin | E12: Casas | F12: Conjuntos | G12: Casas incluidas
A13: Cali | B13: 1 | C13: 46314 | D13: 46321 | E13: 24 | F13: Condominio Los Abedules; Llanos De Pance; Reservas De Pance | G13: 2, 10, 11, 12, 15, 18, 23, 29, 30, 35, 42, 48, 56, 57, 63, 70, 73, 74, 76, 77, 99, 104, 108, 111
A14: Cali | B14: 2 | C14: 46406 | D14: 46406 | E14: 2 | F14: Pance Campestre; Porton De La Rivera | G14: 18PR, 48PC
A15: Costa | B15: 1 | C15: 46314 | D15: 46315 | E15: 5 | F15: Prado Verde Primavera; Terra By Kaia | G15: 18Ap, 23p, 24, 93p, 102p
A16: Costa | B16: 2 | C16: 46363 | D16: 46365 | E16: 6 | F16: Prado Verde Primavera; Terra By Kaia | G16: 55p, 155, 287, 382p, 435p, 446p
A17: Costa | B17: 3 | C17: 46420 | D17: 46422 | E17: 6 | F17: Castellana Real; Condominio Terranova; Prado Verde Primavera | G17: 10p, 15p, 60p, 78T, 86p, 121 CR
A18: Costa | B18: 4 | C18: 46458 | D18: 46461 | E18: 5 | F18: Gerona Club House; Prado Verde Primavera | G18: 9G, 412p, 415p, 425p, 447p
A20: Casas a vigilar en campo (según telemetría de Metrum)
A21: • | B21: Vencidas desde antes de esta fecha: Casa 12 (Los Abedules), Casa 73 (Llanos de Pance), Casa 102p y Casa 23p (Prado Verde) — van en la primera semana.
A22: • | B22: Casa 382p (Prado Verde): el inversor dejó de reportar el 10-oct; verificar comunicación antes de la visita.
A23: • | B23: Generación media baja en últimos 60 días: Casa 111 (2,3 kWh/día), Casa 93p (1,9) y Casa 55p (1,5) — revisar sombreado, limitación de exportación o falla.
A24: • | B24: Equipo reemplazado recientemente: Casa 23p, 48PC, 55p y 121 CR — confirmar si reinician el ciclo.
A26: Antes de ejecutar, confirme los pendientes de la hoja 'Supuestos' (día exacto del mantenimiento de abril en Reservas de Pance, fechas oficiales de energización y capacidad de las cuadrillas).

Sheet Cronograma
A1: Cronograma de mantenimiento preventivo semestral — Sunny
A2: 48 casas · excluye Piloto Promigas y Piloto HUAWEI · ciclo cada 6 meses desde el último mantenimiento (o desde la energización si nunca se ha hecho)
A3: Azul = dato editable · Amarillo = por confirmar · Negro = fórmula. Al ejecutar un mantenimiento: escriba la fecha en 'Último mantenimiento' y la siguiente visita en 'Visita programada'.
A5: Nº | B5: Región | C5: Conjunto / zona | D5: Ciudad | E5: Casa | F5: Inversor | G5: Fecha de energización | H5: Fuente de la energización | I5: Inicio de generación | J5: Nota sobre el inicio de generación | K5: Último mantenimiento realizado | L5: Base del ciclo | M5: Vence (+6 meses) | N5: Visita programada | O5: Holgura vs. vencimiento (días) | P5: Estado | Q5: Visita +6 meses | R5: Visita +12 meses | S5: Visita +18 meses | T5: Observaciones
A6: 1 | B6: Cali | C6: Condominio Los Abedules | D6: Cali | E6: Casa 12 | F6: Livoltek HP3-15KL2 · 15 kW | G6: 46078 | H6: Alta en Metrum (estimada) | I6: Anterior al 01-Jun-2026 | J6: Sin histórico previo en Metrum; ya traía 2,61 MWh | L6: =IF(K6<>"",K6,G6) -> 46078 | M6: =EDATE(L6,Supuestos!$C$5) -> 46259 | N6: 46314 | O6: =N6-M6 -> 55 | P6: =IF(M6<Supuestos!$C$4,"Vencido",IF(M6-Supuestos!$C$4<=Supuestos!$C$6,"En ventana","Al día")) -> Vencido | Q6: =WORKDAY(EDATE(N6,Supuestos!$C$5)-1,1,Festivos) -> 46496 | R6: =WORKDAY(EDATE(Q6,Supuestos!$C$5)-1,1,Festivos) -> 46679 | S6: =WORKDAY(EDATE(R6,Supuestos!$C$5)-1,1,Festivos) -> 46862
A7: 2 | B7: Cali | C7: Llanos De Pance | D7: Cali | E7: Casa 73 | F7: Livoltek HP3-15KL2 · 15 kW | G7: 46004 | H7: Alta en Metrum (estimada) | I7: Anterior al 01-Ago-2026 | J7: Sin histórico previo en Metrum; ya traía 1,76 MWh | L7: =IF(K7<>"",K7,G7) -> 46004 | M7: =EDATE(L7,Supuestos!$C$5) -> 46186 | N7: 46314 | O7: =N7-M7 -> 128 | P7: =IF(M7<Supuestos!$C$4,"Vencido",IF(M7-Supuestos!$C$4<=Supuestos!$C$6,"En ventana","Al día")) -> Vencido | Q7: =WORKDAY(EDATE(N7,Supuestos!$C$5)-1,1,Festivos) -> 46496 | R7: =WORKDAY(EDATE(Q7,Supuestos!$C$5)-1,1,Festivos) -> 46679 | S7: =WORKDAY(EDATE(R7,Supuestos!$C$5)-1,1,Festivos) -> 46862
A8: 3 | B8: Cali | C8: Reservas De Pance | D8: Cali | E8: Casa 2 | F8: Deye SUN-15K-SG01HP3 HV trifásico · 15 kW | G8: 45960 | H8: Alta en Metrum (estimada) | I8: Anterior al 01-Jun-2026 | J8: Sin histórico previo en Metrum; ya traía 4,83 MWh | K8: 46127 | L8: =IF(K8<>"",K8,G8) -> 46127 | M8: =EDATE(L8,Supuestos!$C$5) -> 46310 | N8: 46314 | O8: =N8-M8 -> 4 | P8: =IF(M8<Supuestos!$C$4,"Vencido",IF(M8-Supuestos!$C$4<=Supuestos!$C$6,"En ventana","Al día")) -> En ventana | Q8: =WORKDAY(EDATE(N8,Supuestos!$C$5)-1,1,Festivos) -> 46496 | R8: =WORKDAY(EDATE(Q8,Supuestos!$C$5)-1,1,Festivos) -> 46679 | S8: =WORKDAY(EDATE(R8,Supuestos!$C$5)-1,1,Festivos) -> 46862 | T8: Mantenimiento realizado en abril-2026 (día exacto por confirmar)
A9: 4 | B9: Cali | C9: Reservas De Pance | D9: Cali | E9: Casa 10 | F9: Deye SUN-15K-SG01HP3 HV trifásico · 15 kW | G9: 45968 | H9: Alta en Metrum (estimada) | I9: Anterior al 01-Jun-2026 | J9: Sin histórico previo en Metrum; ya traía 0,86 MWh | K9: 46127 | L9: =IF(K9<>"",K9,G9) -> 46127 | M9: =EDATE(L9,Supuestos!$C$5) -> 46310 | N9: 46314 | O9: =N9-M9 -> 4 | P9: =IF(M9<Supuestos!$C$4,"Vencido",IF(M9-Supuestos!$C$4<=Supuestos!$C$6,"En ventana","Al día")) -> En ventana | Q9: =WORKDAY(EDATE(N9,Supuestos!$C$5)-1,1,Festivos) -> 46496 | R9: =WORKDAY(EDATE(Q9,Supuestos!$C$5)-1,1,Festivos) -> 46679 | S9: =WORKDAY(EDATE(R9,Supuestos!$C$5)-1,1,Festivos) -> 46862 | T9: 2º inversor registrado en Metrum sin telemetría (posible duplicado/retirado); no se considera; Mantenimiento realizado en abril-2026 (día exacto por confirmar)
A10: 5 | B10: Costa - Bolívar | C10: Prado Verde Primavera | D10: Turbaco | E10: Casa 18Ap | F10: Livoltek HP3-10KL2 · 10 kW | G10: 46157 | H10: Alta en Metrum (estimada) | I10: Anterior al 01-Jun-2026 | J10: Sin histórico previo en Metrum; ya traía 0,40 MWh | L10: =IF(K10<>"",K10,G10) -> 46157 | M10: =EDATE(L10,Supuestos!$C$5) -> 46341 | N10: 46314 | O10: =N10-M10 -> -27 | P10: =IF(M10<Supuestos!$C$4,"Vencido",IF(M10-Supuestos!$C$4<=Supuestos!$C$6,"En ventana","Al día")) -> Al día | Q10: =WORKDAY(EDATE(N10,Supuestos!$C$5)-1,1,Festivos) -> 46496 | R10: =WORKDAY(EDATE(Q10,Supuestos!$C$5)-1,1,Festivos) -> 46679 | S10: =WORKDAY(EDATE(R10,Supuestos!$C$5)-1,1,Festivos) -> 46862
A11: 6 | B11: Costa - Bolívar | C11: Prado Verde Primavera | D11: Turbaco | E11: Casa 23p | F11: Livoltek HP3-10KL2 · 10 kW | G11: 46002 | H11: Alta en Metrum (estimada) | I11: Anterior al 01-Jun-2026 | J11: Sin histórico previo en Metrum; ya traía 0,87 MWh | L11: =IF(K11<>"",K11,G11) -> 46002 | M11: =EDATE(L11,Supuestos!$C$5) -> 46184 | N11: 46314 | O11: =N11-M11 -> 130 | P11: =IF(M11<Supuestos!$C$4,"Vencido",IF(M11-Supuestos!$C$4<=Supuestos!$C$6,"En ventana","Al día")) -> Vencido | Q11: =WORKDAY(EDATE(N11,Supuestos!$C$5)-1,1,Festivos) -> 46496 | R11: =WORKDAY(EDATE(Q11,Supuestos!$C$5)-1,1,Festivos) -> 46679 | S11: =WORKDAY(EDATE(R11,Supuestos!$C$5)-1,1,Festivos) -> 46862 | T11: Inversor reemplazado (equipo anterior sin datos desde 2026-08-05)
A12: 7 | B12: Costa - Bolívar | C12: Prado Verde Primavera | D12: Turbaco | E12: Casa 93p | F12: Deye SUN-15K-SG01HP3 · 15 kW | G12: 46156 | H12: Alta en Metrum (estimada) | I12: 46174 | J12: ≈ 01-jun-2026 (odómetro casi en cero al inicio de la telemetría) | L12: =IF(K12<>"",K12,G12) -> 46156 | M12: =EDATE(L12,Supuestos!$C$5) -> 46340 | N12: 46314 | O12: =N12-M12 -> -26 | P12: =IF(M12<Supuestos!$C$4,"Vencido",IF(M12-Supuestos!$C$4<=Supuestos!$C$6,"En ventana","Al día")) -> En ventana | Q12: =WORKDAY(EDATE(N12,Supuestos!$C$5)-1,1,Festivos) -> 46496 | R12: =WORKDAY(EDATE(Q12,Supuestos!$C$5)-1,1,Festivos) -> 46679 | S12: =WORKDAY(EDATE(R12,Supuestos!$C$5)-1,1,Festivos) -> 46862 | T12: Energizada 14-May pero empezó a generar 01-Jun (18 d después); Generación media baja (1.9 kWh/día, últimos 60 d): revisar en la visita
A13: 8 | B13: Costa - Bolívar | C13: Prado Verde Primavera | D13: Turbaco | E13: Casa 102p | F13: Livoltek HP3-10KL2 · 10 kW | G13: 45980 | H13: Alta en Metrum (estimada) | I13: Anterior al 01-Jun-2026 | J13: Sin histórico previo en Metrum; ya traía 1,04 MWh | L13: =IF(K13<>"",K13,G13) -> 45980 | M13: =EDATE(L13,Supuestos!$C$5) -> 46161 | N13: 46314 | O13: =N13-M13 -> 153 | P13: =IF(M13<Supuestos!$C$4,"Vencido",IF(M13-Supuestos!$C$4<=Supuestos!$C$6,"En ventana","Al día")) -> Vencido | Q13: =WORKDAY(EDATE(N13,Supuestos!$C$5)-1,1,Festivos) -> 46496 | R13: =WORKDAY(EDATE(Q13,Supuestos!$C$5)-1,1,Festivos) -> 46679 | S13: =WORKDAY(EDATE(R13,Supuestos!$C$5)-1,1,Festivos) -> 46862
A14: 9 | B14: Cali | C14: Reservas De Pance | D14: Cali | E14: Casa 11 | F14: Livoltek HP3-15KL2 · 15 kW | G14: 45989 | H14: Alta en Metrum (estimada) | I14: Anterior al 01-Jun-2026 | J14: Sin histórico previo en Metrum; ya traía 1,81 MWh | K14: 46127 | L14: =IF(K14<>"",K14,G14) -> 46127 | M14: =EDATE(L14,Supuestos!$C$5) -> 46310 | N14: 46315 | O14: =N14-M14 -> 5 | P14: =IF(M14<Supuestos!$C$4,"Vencido",IF(M14-Supuestos!$C$4<=Supuestos!$C$6,"En ventana","Al día")) -> En ventana | Q14: =WORKDAY(EDATE(N14,Supuestos!$C$5)-1,1,Festivos) -> 46497 | R14: =WORKDAY(EDATE(Q14,Supuestos!$C$5)-1,1,Festivos) -> 46680 | S14: =WORKDAY(EDATE(R14,Supuestos!$C$5)-1,1,Festivos) -> 46863 | T14: Mantenimiento realizado en abril-2026 (día exacto por confirmar)
A15: 10 | B15: Cali | C15: Reservas De Pance | D15: Cali | E15: Casa 15 | F15: Livoltek HP3-15KL2 · 15 kW | G15: 46064 | H15: Alta en Metrum (estimada) | I15: Anterior al 01-Jun-2026 | J15: Sin histórico previo en Metrum; ya traía 3,00 MWh | K15: 46127 | L15: =IF(K15<>"",K15,G15) -> 46127 | M15: =EDATE(L15,Supuestos!$C$5) -> 46310 | N15: 46315 | O15: =N15-M15 -> 5 | P15: =IF(M15<Supuestos!$C$4,"Vencido",IF(M15-Supuestos!$C$4<=Supuestos!$C$6,"En ventana","Al día")) -> En ventana | Q15: =WORKDAY(EDATE(N15,Supuestos!$C$5)-1,1,Festivos) -> 46497 | R15: =WORKDAY(EDATE(Q15,Supuestos!$C$5)-1,1,Festivos) -> 46680 | S15: =WORKDAY(EDATE(R15,Supuestos!$C$5)-1,1,Festivos) -> 46863 | T15: Mantenimiento realizado en abril-2026 (día exacto por confirmar)
A16: 11 | B16: Cali | C16: Reservas De Pance | D16: Cali | E16: Casa 18 | F16: Livoltek HP3-10KL2 · 10 kW | G16: 46009 | H16: Alta en Metrum (estimada) | I16: Anterior al 01-Jun-2026 | J16: Sin histórico previo en Metrum; ya traía 1,56 MWh | K16: 46127 | L16: =IF(K16<>"",K16,G16) -> 46127 | M16: =EDATE(L16,Supuestos!$C$5) -> 46310 | N16: 46315 | O16: =N16-M16 -> 5 | P16: =IF(M16<Supuestos!$C$4,"Vencido",IF(M16-Supuestos!$C$4<=Supuestos!$C$6,"En ventana","Al día")) -> En ventana | Q16: =WORKDAY(EDATE(N16,Supuestos!$C$5)-1,1,Festivos) -> 46497 | R16: =WORKDAY(EDATE(Q16,Supuestos!$C$5)-1,1,Festivos) -> 46680 | S16: =WORKDAY(EDATE(R16,Supuestos!$C$5)-1,1,Festivos) -> 46863 | T16: Mantenimiento realizado en abril-2026 (día exacto por confirmar)
A17: 12 | B17: Cali | C17: Reservas De Pance | D17: Cali | E17: Casa 23 | F17: Livoltek HP3-10KL2 · 10 kW | G17: 45989 | H17: Alta en Metrum (estimada) | I17: Anterior al 01-Jun-2026 | J17: Sin histórico previo en Metrum; ya traía 3,14 MWh | K17: 46127 | L17: =IF(K17<>"",K17,G17) -> 46127 | M17: =EDATE(L17,Supuestos!$C$5) -> 46310 | N17: 46315 | O17: =N17-M17 -> 5 | P17: =IF(M17<Supuestos!$C$4,"Vencido",IF(M17-Supuestos!$C$4<=Supuestos!$C$6,"En ventana","Al día")) -> En ventana | Q17: =WORKDAY(EDATE(N17,Supuestos!$C$5)-1,1,Festivos) -> 46497 | R17: =WORKDAY(EDATE(Q17,Supuestos!$C$5)-1,1,Festivos) -> 46680 | S17: =WORKDAY(EDATE(R17,Supuestos!$C$5)-1,1,Festivos) -> 46863 | T17: Mantenimiento realizado en abril-2026 (día exacto por confirmar)
A18: 13 | B18: Costa - Atlántico | C18: Terra By Kaia | D18: Barranquilla | E18: Casa 24 | F18: Livoltek HP3-15KL2 · 15 kW | G18: 46140 | H18: Alta en Metrum (estimada) | I18: Anterior al 01-Jun-2026 | J18: Sin histórico previo en Metrum; ya traía 1,06 MWh | L18: =IF(K18<>"",K18,G18) -> 46140 | M18: =EDATE(L18,Supuestos!$C$5) -> 46323 | N18: 46315 | O18: =N18-M18 -> -8 | P18: =IF(M18<Supuestos!$C$4,"Vencido",IF(M18-Supuestos!$C$4<=Supuestos!$C$6,"En ventana","Al día")) -> En ventana | Q18: =WORKDAY(EDATE(N18,Supuestos!$C$5)-1,1,Festivos) -> 46497 | R18: =WORKDAY(EDATE(Q18,Supuestos!$C$5)-1,1,Festivos) -> 46680 | S18: =WORKDAY(EDATE(R18,Supuestos!$C$5)-1,1,Festivos) -> 46863
A19: 14 | B19: Cali | C19: Reservas De Pance | D19: Cali | E19: Casa 29 | F19: Livoltek HP3-10KL2 · 10 kW | G19: 46010 | H19: Alta en Metrum (estimada) | I19: Anterior al 01-Jun-2026 | J19: Sin histórico previo en Metrum; ya traía 2,41 MWh | K19: 46127 | L19: =IF(K19<>"",K19,G19) -> 46127 | M19: =EDATE(L19,Supuestos!$C$5) -> 46310 | N19: 46316 | O19: =N19-M19 -> 6 | P19: =IF(M19<Supuestos!$C$4,"Vencido",IF(M19-Supuestos!$C$4<=Supuestos!$C$6,"En ventana","Al día")) -> En ventana | Q19: =WORKDAY(EDATE(N19,Supuestos!$C$5)-1,1,Festivos) -> 46498 | R19: =WORKDAY(EDATE(Q19,Supuestos!$C$5)-1,1,Festivos) -> 46681 | S19: =WORKDAY(EDATE(R19,Supuestos!$C$5)-1,1,Festivos) -> 46864 | T19: Mantenimiento realizado en abril-2026 (día exacto por confirmar)
A20: 15 | B20: Cali | C20: Reservas De Pance | D20: Cali | E20: Casa 30 | F20: Livoltek HP3-10KL2 · 10 kW | G20: 45966 | H20: Alta en Metrum (estimada) | I20: Anterior al 01-Jun-2026 | J20: Sin histórico previo en Metrum; ya traía 2,75 MWh | K20: 46127 | L20: =IF(K20<>"",K20,G20) -> 46127 | M20: =EDATE(L20,Supuestos!$C$5) -> 46310 | N20: 46316 | O20: =N20-M20 -> 6 | P20: =IF(M20<Supuestos!$C$4,"Vencido",IF(M20-Supuestos!$C$4<=Supuestos!$C$6,"En ventana","Al día")) -> En ventana | Q20: =WORKDAY(EDATE(N20,Supuestos!$C$5)-1,1,Festivos) -> 46498 | R20: =WORKDAY(EDATE(Q20,Supuestos!$C$5)-1,1,Festivos) -> 46681 | S20: =WORKDAY(EDATE(R20,Supuestos!$C$5)-1,1,Festivos) -> 46864 | T20: Mantenimiento realizado en abril-2026 (día exacto por confirmar)
A21: 16 | B21: Cali | C21: Reservas De Pance | D21: Cali | E21: Casa 35 | F21: Livoltek HP3-10KL2 · 10 kW | G21: 46063 | H21: Alta en Metrum (estimada) | I21: Anterior al 01-Jun-2026 | J21: Sin histórico previo en Metrum; ya traía 1,34 MWh | K21: 46127 | L21: =IF(K21<>"",K21,G21) -> 46127 | M21: =EDATE(L21,Supuestos!$C$5) -> 46310 | N21: 46316 | O21: =N21-M21 -> 6 | P21: =IF(M21<Supuestos!$C$4,"Vencido",IF(M21-Supuestos!$C$4<=Supuestos!$C$6,"En ventana","Al día")) -> En ventana | Q21: =WORKDAY(EDATE(N21,Supuestos!$C$5)-1,1,Festivos) -> 46498 | R21: =WORKDAY(EDATE(Q21,Supuestos!$C$5)-1,1,Festivos) -> 46681 | S21: =WORKDAY(EDATE(R21,Supuestos!$C$5)-1,1,Festivos) -> 46864 | T21: Mantenimiento realizado en abril-2026 (día exacto por confirmar)
A22: 17 | B22: Cali | C22: Reservas De Pance | D22: Cali | E22: Casa 42 | F22: Livoltek HP3-10KL2 · 10 kW | G22: 45966 | H22: Alta en Metrum (estimada) | I22: Anterior al 01-Jun-2026 | J22: Sin histórico previo en Metrum; ya traía 2,53 MWh | K22: 46127 | L22: =IF(K22<>"",K22,G22) -> 46127 | M22: =EDATE(L22,Supuestos!$C$5) -> 46310 | N22: 46316 | O22: =N22-M22 -> 6 | P22: =IF(M22<Supuestos!$C$4,"Vencido",IF(M22-Supuestos!$C$4<=Supuestos!$C$6,"En ventana","Al día")) -> En ventana | Q22: =WORKDAY(EDATE(N22,Supuestos!$C$5)-1,1,Festivos) -> 46498 | R22: =WORKDAY(EDATE(Q22,Supuestos!$C$5)-1,1,Festivos) -> 46681 | S22: =WORKDAY(EDATE(R22,Supuestos!$C$5)-1,1,Festivos) -> 46864 | T22: Mantenimiento realizado en abril-2026 (día exacto por confirmar)
A23: 18 | B23: Cali | C23: Reservas De Pance | D23: Cali | E23: Casa 48 | F23: Livoltek HP3-10KL2 · 10 kW | G23: 46015 | H23: Alta en Metrum (estimada) | I23: Anterior al 01-Jun-2026 | J23: Sin histórico previo en Metrum; ya traía 1,41 MWh | K23: 46127 | L23: =IF(K23<>"",K23,G23) -> 46127 | M23: =EDATE(L23,Supuestos!$C$5) -> 46310 | N23: 46317 | O23: =N23-M23 -> 7 | P23: =IF(M23<Supuestos!$C$4,"Vencido",IF(M23-Supuestos!$C$4<=Supuestos!$C$6,"En ventana","Al día")) -> En ventana | Q23: =WORKDAY(EDATE(N23,Supuestos!$C$5)-1,1,Festivos) -> 46499 | R23: =WORKDAY(EDATE(Q23,Supuestos!$C$5)-1,1,Festivos) -> 46682 | S23: =WORKDAY(EDATE(R23,Supuestos!$C$5)-1,1,Festivos) -> 46867 | T23: Mantenimiento realizado en abril-2026 (día exacto por confirmar)
A24: 19 | B24: Cali | C24: Reservas De Pance | D24: Cali | E24: Casa 56 | F24: Livoltek HP3-10KL2 · 10 kW | G24: 45960 | H24: Alta en Metrum (estimada) | I24: Anterior al 01-Jun-2026 | J24: Sin histórico previo en Metrum; ya traía 3,09 MWh | K24: 46127 | L24: =IF(K24<>"",K24,G24) -> 46127 | M24: =EDATE(L24,Supuestos!$C$5) -> 46310 | N24: 46317 | O24: =N24-M24 -> 7 | P24: =IF(M24<Supuestos!$C$4,"Vencido",IF(M24-Supuestos!$C$4<=Supuestos!$C$6,"En ventana","Al día")) -> En ventana | Q24: =WORKDAY(EDATE(N24,Supuestos!$C$5)-1,1,Festivos) -> 46499 | R24: =WORKDAY(EDATE(Q24,Supuestos!$C$5)-1,1,Festivos) -> 46682 | S24: =WORKDAY(EDATE(R24,Supuestos!$C$5)-1,1,Festivos) -> 46867 | T24: Mantenimiento realizado en abril-2026 (día exacto por confirmar)
A25: 20 | B25: Cali | C25: Reservas De Pance | D25: Cali | E25: Casa 57 | F25: Livoltek HP3-10KL2 · 10 kW | G25: 46010 | H25: Alta en Metrum (estimada) | I25: Anterior al 01-Jun-2026 | J25: Sin histórico previo en Metrum; ya traía 1,99 MWh | K25: 46127 | L25: =IF(K25<>"",K25,G25) -> 46127 | M25: =EDATE(L25,Supuestos!$C$5) -> 46310 | N25: 46317 | O25: =N25-M25 -> 7 | P25: =IF(M25<Supuestos!$C$4,"Vencido",IF(M25-Supuestos!$C$4<=Supuestos!$C$6,"En ventana","Al día")) -> En ventana | Q25: =WORKDAY(EDATE(N25,Supuestos!$C$5)-1,1,Festivos) -> 46499 | R25: =WORKDAY(EDATE(Q25,Supuestos!$C$5)-1,1,Festivos) -> 46682 | S25: =WORKDAY(EDATE(R25,Supuestos!$C$5)-1,1,Festivos) -> 46867 | T25: Mantenimiento realizado en abril-2026 (día exacto por confirmar)
A26: 21 | B26: Cali | C26: Reservas De Pance | D26: Cali | E26: Casa 63 | F26: Deye LV trifásico · 6 kW | G26: 46083 | H26: Alta en Metrum (estimada) | I26: Anterior al 01-Jun-2026 | J26: Sin histórico previo en Metrum; ya traía 2,07 MWh | K26: 46127 | L26: =IF(K26<>"",K26,G26) -> 46127 | M26: =EDATE(L26,Supuestos!$C$5) -> 46310 | N26: 46317 | O26: =N26-M26 -> 7 | P26: =IF(M26<Supuestos!$C$4,"Vencido",IF(M26-Supuestos!$C$4<=Supuestos!$C$6,"En ventana","Al día")) -> En ventana | Q26: =WORKDAY(EDATE(N26,Supuestos!$C$5)-1,1,Festivos) -> 46499 | R26: =WORKDAY(EDATE(Q26,Supuestos!$C$5)-1,1,Festivos) -> 46682 | S26: =WORKDAY(EDATE(R26,Supuestos!$C$5)-1,1,Festivos) -> 46867 | T26: Mantenimiento realizado en abril-2026 (día exacto por confirmar)
A27: 22 | B27: Cali | C27: Reservas De Pance | D27: Cali | E27: Casa 70 | F27: Deye HV trifásico · 15 kW | G27: 46002 | H27: Alta en Metrum (estimada) | I27: Anterior al 01-Jun-2026 | J27: Sin histórico previo en Metrum; ya traía 1,94 MWh | K27: 46127 | L27: =IF(K27<>"",K27,G27) -> 46127 | M27: =EDATE(L27,Supuestos!$C$5) -> 46310 | N27: 46318 | O27: =N27-M27 -> 8 | P27: =IF(M27<Supuestos!$C$4,"Vencido",IF(M27-Supuestos!$C$4<=Supuestos!$C$6,"En ventana","Al día")) -> En ventana | Q27: =WORKDAY(EDATE(N27,Supuestos!$C$5)-1,1,Festivos) -> 46500 | R27: =WORKDAY(EDATE(Q27,Supuestos!$C$5)-1,1,Festivos) -> 46685 | S27: =WORKDAY(EDATE(R27,Supuestos!$C$5)-1,1,Festivos) -> 46868 | T27: Mantenimiento realizado en abril-2026 (día exacto por confirmar)
A28: 23 | B28: Cali | C28: Reservas De Pance | D28: Cali | E28: Casa 74 | F28: Deye SUN-15K-SG01HP3 · 15 kW | G28: 46004 | H28: Alta en Metrum (estimada) | I28: Anterior al 01-Jun-2026 | J28: Sin histórico previo en Metrum; ya traía 0,47 MWh | K28: 46127 | L28: =IF(K28<>"",K28,G28) -> 46127 | M28: =EDATE(L28,Supuestos!$C$5) -> 46310 | N28: 46318 | O28: =N28-M28 -> 8 | P28: =IF(M28<Supuestos!$C$4,"Vencido",IF(M28-Supuestos!$C$4<=Supuestos!$C$6,"En ventana","Al día")) -> En ventana | Q28: =WORKDAY(EDATE(N28,Supuestos!$C$5)-1,1,Festivos) -> 46500 | R28: =WORKDAY(EDATE(Q28,Supuestos!$C$5)-1,1,Festivos) -> 46685 | S28: =WORKDAY(EDATE(R28,Supuestos!$C$5)-1,1,Festivos) -> 46868 | T28: Mantenimiento realizado en abril-2026 (día exacto por confirmar)
A29: 24 | B29: Cali | C29: Reservas De Pance | D29: Cali | E29: Casa 76 | F29: Livoltek HP3-15KL2 · 15 kW | G29: 45980 | H29: Alta en Metrum (estimada) | I29: Anterior al 01-Jun-2026 | J29: Sin histórico previo en Metrum; ya traía 3,13 MWh | K29: 46127 | L29: =IF(K29<>"",K29,G29) -> 46127 | M29: =EDATE(L29,Supuestos!$C$5) -> 46310 | N29: 46318 | O29: =N29-M29 -> 8 | P29: =IF(M29<Supuestos!$C$4,"Vencido",IF(M29-Supuestos!$C$4<=Supuestos!$C$6,"En ventana","Al día")) -> En ventana | Q29: =WORKDAY(EDATE(N29,Supuestos!$C$5)-1,1,Festivos) -> 46500 | R29: =WORKDAY(EDATE(Q29,Supuestos!$C$5)-1,1,Festivos) -> 46685 | S29: =WORKDAY(EDATE(R29,Supuestos!$C$5)-1,1,Festivos) -> 46868 | T29: Mantenimiento realizado en abril-2026 (día exacto por confirmar)
A30: 25 | B30: Cali | C30: Reservas De Pance | D30: Cali | E30: Casa 77 | F30: Livoltek HP3-10KL2 · 10 kW | G30: 45966 | H30: Alta en Metrum (estimada) | I30: Anterior al 01-Jun-2026 | J30: Sin histórico previo en Metrum; ya traía 2,71 MWh | K30: 46127 | L30: =IF(K30<>"",K30,G30) -> 46127 | M30: =EDATE(L30,Supuestos!$C$5) -> 46310 | N30: 46318 | O30: =N30-M30 -> 8 | P30: =IF(M30<Supuestos!$C$4,"Vencido",IF(M30-Supuestos!$C$4<=Supuestos!$C$6,"En ventana","Al día")) -> En ventana | Q30: =WORKDAY(EDATE(N30,Supuestos!$C$5)-1,1,Festivos) -> 46500 | R30: =WORKDAY(EDATE(Q30,Supuestos!$C$5)-1,1,Festivos) -> 46685 | S30: =WORKDAY(EDATE(R30,Supuestos!$C$5)-1,1,Festivos) -> 46868 | T30: Mantenimiento realizado en abril-2026 (día exacto por confirmar)
... A34: 29 | B34: Cali | C34: Reservas De Pance | D34: Cali | E34: Casa 111 | F34: Deye SUN-15K-SG01HP3 HV trifásico · 15 kW | G34: 46002 | H34: Alta en Metrum (estimada) | I34: Anterior al 01-Jun-2026 | J34: Sin histórico previo en Metrum; ya traía 0,41 MWh | K34: 46127 | L34: =IF(K34<>"",K34,G34) -> 46127 | M34: =EDATE(L34,Supuestos!$C$5) -> 46310 | N34: 46321 | O34: =N34-M34 -> 11 | P34: =IF(M34<Supuestos!$C$4,"Vencido",IF(M34-Supuestos!$C$4<=Supuestos!$C$6,"En ventana","Al día")) -> En ventana | Q34: =WORKDAY(EDATE(N34,Supuestos!$C$5)-1,1,Festivos) -> 46503 | R34: =WORKDAY(EDATE(Q34,Supuestos!$C$5)-1,1,Festivos) -> 46686 | S34: =WORKDAY(EDATE(R34,Supuestos!$C$5)-1,1,Festivos) -> 46869 | T34: Generación media baja (2.3 kWh/día, últimos 60 d): revisar en la visita; Mantenimiento realizado en abril-2026 (día exacto por confirmar)
A35: 30 | B35: Costa - Bolívar | C35: Prado Verde Primavera | D35: Turbaco | E35: Casa 55p | F35: Deye HP3-15KL2 · 15 kW | G35: 46175 | H35: Telemetría Metrum (1er dato) | I35: 46176 | L35: =IF(K35<>"",K35,G35) -> 46175 | M35: =EDATE(L35,Supuestos!$C$5) -> 46358 | N35: 46363 | O35: =N35-M35 -> 5 | P35: =IF(M35<Supuestos!$C$4,"Vencido",IF(M35-Supuestos!$C$4<=Supuestos!$C$6,"En ventana","Al día")) -> Al día | Q35: =WORKDAY(EDATE(N35,Supuestos!$C$5)-1,1,Festivos) -> 46546 | R35: =WORKDAY(EDATE(Q35,Supuestos!$C$5)-1,1,Festivos) -> 46730 | S35: =WORKDAY(EDATE(R35,Supuestos!$C$5)-1,1,Festivos) -> 46913 | T35: Inversor reemplazado (equipo anterior sin datos desde 2026-09-02); Generación media baja (1.5 kWh/día, últimos 60 d): revisar en la visita
A36: 31 | B36: Costa - Bolívar | C36: Prado Verde Primavera | D36: Turbaco | E36: Casa 382p | F36: Deye SUN-15K-SG01HP3 · 15 kW | G36: 46204 | H36: Telemetría Metrum (1er dato) | I36: Anterior al 02-Jul-2026 | J36: Sin histórico previo en Metrum; ya traía 0,08 MWh | L36: =IF(K36<>"",K36,G36) -> 46204 | M36: =EDATE(L36,Supuestos!$C$5) -> 46388 | N36: 46363 | O36: =N36-M36 -> -25 | P36: =IF(M36<Supuestos!$C$4,"Vencido",IF(M36-Supuestos!$C$4<=Supuestos!$C$6,"En ventana","Al día")) -> Al día | Q36: =WORKDAY(EDATE(N36,Supuestos!$C$5)-1,1,Festivos) -> 46546 | R36: =WORKDAY(EDATE(Q36,Supuestos!$C$5)-1,1,Festivos) -> 46730 | S36: =WORKDAY(EDATE(R36,Supuestos!$C$5)-1,1,Festivos) -> 46913 | T36: Inversor sin datos desde 2026-10-10: verificar comunicación
A37: 32 | B37: Costa - Bolívar | C37: Prado Verde Primavera | D37: Turbaco | E37: Casa 435p | F37: Livoltek HP3-10KL2 · 10 kW | G37: 46178 | H37: Telemetría Metrum (1er dato) | I37: 46179 | L37: =IF(K37<>"",K37,G37) -> 46178 | M37: =EDATE(L37,Supuestos!$C$5) -> 46361 | N37: 46363 | O37: =N37-M37 -> 2 | P37: =IF(M37<Supuestos!$C$4,"Vencido",IF(M37-Supuestos!$C$4<=Supuestos!$C$6,"En ventana","Al día")) -> Al día | Q37: =WORKDAY(EDATE(N37,Supuestos!$C$5)-1,1,Festivos) -> 46546 | R37: =WORKDAY(EDATE(Q37,Supuestos!$C$5)-1,1,Festivos) -> 46730 | S37: =WORKDAY(EDATE(R37,Supuestos!$C$5)-1,1,Festivos) -> 46913
A38: 33 | B38: Costa - Bolívar | C38: Prado Verde Primavera | D38: Turbaco | E38: Casa 446p | F38: Deye SUN-15K-SG01HP3 HV trifásico · 15 kW | G38: 46182 | H38: Telemetría Metrum (1er dato) | I38: 46183 | L38: =IF(K38<>"",K38,G38) -> 46182 | M38: =EDATE(L38,Supuestos!$C$5) -> 46365 | N38: 46363 | O38: =N38-M38 -> -2 | P38: =IF(M38<Supuestos!$C$4,"Vencido",IF(M38-Supuestos!$C$4<=Supuestos!$C$6,"En ventana","Al día")) -> Al día | Q38: =WORKDAY(EDATE(N38,Supuestos!$C$5)-1,1,Festivos) -> 46546 | R38: =WORKDAY(EDATE(Q38,Supuestos!$C$5)-1,1,Festivos) -> 46730 | S38: =WORKDAY(EDATE(R38,Supuestos!$C$5)-1,1,Festivos) -> 46913
A39: 34 | B39: Costa - Atlántico | C39: Terra By Kaia | D39: Barranquilla | E39: Casa 155 | F39: Livoltek HP3-15KL2 · 15 kW | G39: 46206 | H39: Telemetría Metrum (1er dato) | I39: 46207 | L39: =IF(K39<>"",K39,G39) -> 46206 | M39: =EDATE(L39,Supuestos!$C$5) -> 46390 | N39: 46365 | O39: =N39-M39 -> -25 | P39: =IF(M39<Supuestos!$C$4,"Vencido",IF(M39-Supuestos!$C$4<=Supuestos!$C$6,"En ventana","Al día")) -> Al día | Q39: =WORKDAY(EDATE(N39,Supuestos!$C$5)-1,1,Festivos) -> 46547 | R39: =WORKDAY(EDATE(Q39,Supuestos!$C$5)-1,1,Festivos) -> 46730 | S39: =WORKDAY(EDATE(R39,Supuestos!$C$5)-1,1,Festivos) -> 46913
A40: 35 | B40: Costa - Atlántico | C40: Terra By Kaia | D40: Barranquilla | E40: Casa 287 | F40: Livoltek HP3-10KL2 · 10 kW | G40: 46198 | H40: Telemetría Metrum (1er dato) | I40: 46199 | L40: =IF(K40<>"",K40,G40) -> 46198 | M40: =EDATE(L40,Supuestos!$C$5) -> 46381 | N40: 46365 | O40: =N40-M40 -> -16 | P40: =IF(M40<Supuestos!$C$4,"Vencido",IF(M40-Supuestos!$C$4<=Supuestos!$C$6,"En ventana","Al día")) -> Al día | Q40: =WORKDAY(EDATE(N40,Supuestos!$C$5)-1,1,Festivos) -> 46547 | R40: =WORKDAY(EDATE(Q40,Supuestos!$C$5)-1,1,Festivos) -> 46730 | S40: =WORKDAY(EDATE(R40,Supuestos!$C$5)-1,1,Festivos) -> 46913
A41: 36 | B41: Cali | C41: Pance Campestre | D41: Cali | E41: Casa 48PC | F41: Deye SUN-15K-SG01HP3 HV trifásico · 15 kW | G41: 46238 | H41: Telemetría Metrum (1er dato) | I41: 46239 | L41: =IF(K41<>"",K41,G41) -> 46238 | M41: =EDATE(L41,Supuestos!$C$5) -> 46422 | N41: 46406 | O41: =N41-M41 -> -16 | P41: =IF(M41<Supuestos!$C$4,"Vencido",IF(M41-Supuestos!$C$4<=Supuestos!$C$6,"En ventana","Al día")) -> Al día | Q41: =WORKDAY(EDATE(N41,Supuestos!$C$5)-1,1,Festivos) -> 46587 | R41: =WORKDAY(EDATE(Q41,Supuestos!$C$5)-1,1,Festivos) -> 46771 | S41: =WORKDAY(EDATE(R41,Supuestos!$C$5)-1,1,Festivos) -> 46953 | T41: Inversor reemplazado (equipo anterior sin datos desde 2026-08-22)
A42: 37 | B42: Cali | C42: Porton De La Rivera | D42: Cali | E42: Casa 18PR | F42: Deye SUN-15K-SG01HP3 · 15 kW | G42: 46217 | H42: Telemetría Metrum (1er dato) | I42: Anterior al 15-Jul-2026 | J42: Sin histórico previo en Metrum; ya traía 0,06 MWh | L42: =IF(K42<>"",K42,G42) -> 46217 | M42: =EDATE(L42,Supuestos!$C$5) -> 46401 | N42: 46406 | O42: =N42-M42 -> 5 | P42: =IF(M42<Supuestos!$C$4,"Vencido",IF(M42-Supuestos!$C$4<=Supuestos!$C$6,"En ventana","Al día")) -> Al día | Q42: =WORKDAY(EDATE(N42,Supuestos!$C$5)-1,1,Festivos) -> 46587 | R42: =WORKDAY(EDATE(Q42,Supuestos!$C$5)-1,1,Festivos) -> 46771 | S42: =WORKDAY(EDATE(R42,Supuestos!$C$5)-1,1,Festivos) -> 46953
A43: 38 | B43: Costa - Bolívar | C43: Condominio Terranova | D43: Cartagena | E43: Casa 78T | F43: Deye SUN-15K-SG01HP3 · 15 kW | G43: 46231 | H43: Telemetría Metrum (1er dato) | I43: 46232 | L43: =IF(K43<>"",K43,G43) -> 46231 | M43: =EDATE(L43,Supuestos!$C$5) -> 46415 | N43: 46420 | O43: =N43-M43 -> 5 | P43: =IF(M43<Supuestos!$C$4,"Vencido",IF(M43-Supuestos!$C$4<=Supuestos!$C$6,"En ventana","Al día")) -> Al día | Q43: =WORKDAY(EDATE(N43,Supuestos!$C$5)-1,1,Festivos) -> 46601 | R43: =WORKDAY(EDATE(Q43,Supuestos!$C$5)-1,1,Festivos) -> 46785 | S43: =WORKDAY(EDATE(R43,Supuestos!$C$5)-1,1,Festivos) -> 46967
A44: 39 | B44: Costa - Bolívar | C44: Prado Verde Primavera | D44: Turbaco | E44: Casa 10p | F44: Livoltek HP3-10KL2 · 10 kW | G44: 46246 | H44: Telemetría Metrum (1er dato) | I44: 46248 | L44: =IF(K44<>"",K44,G44) -> 46246 | M44: =EDATE(L44,Supuestos!$C$5) -> 46430 | N44: 46420 | O44: =N44-M44 -> -10 | P44: =IF(M44<Supuestos!$C$4,"Vencido",IF(M44-Supuestos!$C$4<=Supuestos!$C$6,"En ventana","Al día")) -> Al día | Q44: =WORKDAY(EDATE(N44,Supuestos!$C$5)-1,1,Festivos) -> 46601 | R44: =WORKDAY(EDATE(Q44,Supuestos!$C$5)-1,1,Festivos) -> 46785 | S44: =WORKDAY(EDATE(R44,Supuestos!$C$5)-1,1,Festivos) -> 46967
...

Sheet Agenda inicial
A1: Agenda inicial de visitas (primer ciclo)
A2: Plan generado el 15-oct-2026 con 1 cuadrilla en Cali y 1 en la Costa, 4 casas/día. Es una foto inicial: si mueve fechas en 'Cronograma', actualice esta hoja o pídame regenerarla.
A4: Fecha | B4: Día | C4: Cuadrilla / región | D4: Conjunto | E4: Casas | F4: N° casas
A5: 46314 | B5: lun | C5: Cali | D5: Condominio Los Abedules | E5: Casa 12 | F5: 1
A6: 46314 | B6: lun | C6: Cali | D6: Llanos De Pance | E6: Casa 73 | F6: 1
A7: 46314 | B7: lun | C7: Cali | D7: Reservas De Pance | E7: Casa 2, Casa 10 | F7: 2
A8: 46314 | B8: lun | C8: Costa | D8: Prado Verde Primavera | E8: Casa 18Ap, Casa 23p, Casa 93p, Casa 102p | F8: 4
A9: 46315 | B9: mar | C9: Cali | D9: Reservas De Pance | E9: Casa 11, Casa 15, Casa 18, Casa 23 | F9: 4
A10: 46315 | B10: mar | C10: Costa | D10: Terra By Kaia | E10: Casa 24 | F10: 1
A11: 46316 | B11: mié | C11: Cali | D11: Reservas De Pance | E11: Casa 29, Casa 30, Casa 35, Casa 42 | F11: 4
A12: 46317 | B12: jue | C12: Cali | D12: Reservas De Pance | E12: Casa 48, Casa 56, Casa 57, Casa 63 | F12: 4
A13: 46318 | B13: vie | C13: Cali | D13: Reservas De Pance | E13: Casa 70, Casa 74, Casa 76, Casa 77 | F13: 4
A14: 46321 | B14: lun | C14: Cali | D14: Reservas De Pance | E14: Casa 99, Casa 104, Casa 108, Casa 111 | F14: 4
A15: 46363 | B15: lun | C15: Costa | D15: Prado Verde Primavera | E15: Casa 55p, Casa 382p, Casa 435p, Casa 446p | F15: 4
A16: 46365 | B16: mié | C16: Costa | D16: Terra By Kaia | E16: Casa 155, Casa 287 | F16: 2
... A24: 46461 | B24: lun | C24: Costa | D24: Gerona Club House | E24: Casa 9G | F24: 1

Sheet Calendario
A1: Carga de visitas por mes (fórmulas sobre 'Cronograma')
A2: Cuenta las visitas programadas y los ciclos +6, +12 y +18 meses. Se actualiza al mover fechas en 'Cronograma'.
A4: Por región (cuadrilla)
A5: Mes → | B5: 46296 | C5: =EDATE(B5,1) -> 46327 | D5: =EDATE(C5,1) -> 46357 | E5: =EDATE(D5,1) -> 46388 | F5: =EDATE(E5,1) -> 46419 | G5: =EDATE(F5,1) -> 46447 | H5: =EDATE(G5,1) -> 46478 | I5: =EDATE(H5,1) -> 46508 | J5: =EDATE(I5,1) -> 46539 | ... Y5: =EDATE(X5,1) -> 46997 | Z5: Total
A6: Cali | B6: =COUNTIFS(Cronograma!$B$6:$B$53,$A6,Cronograma!$N$6:$N$53,">="&B$5,Cronograma!$N$6:$N$53,"<"&EDATE(B$5,1))+COUNTIFS(Cronograma!$B$6:$B$53,$A6,Cronograma!$Q$6:$Q$53,">="&B$5,Cronograma!$Q$6:$Q$53,"<"&EDATE(B$5,1))+COUNTIFS(Cronograma!$B$6:$B$53,$A6,Cronograma!$R$6:$R$53,">="&B$5,Cronograma!$R$6:$R$53,"<"&EDATE(B$5,1))+COUNTIFS(Cronograma!$B$6:$B$53,$A6,Cronograma!$S$6:$S$53,">="&B$5,Cronograma!$S$6:$S$53,"<"&EDATE(B$5,1)) -> 24 | C6: =COUNTIFS(Cronograma!$B$6:$B$53,$A6,Cronograma!$N$6:$N$53,">="&C$5,Cronograma!$N$6:$N$53,"<"&EDATE(C$5,1))+COUNTIFS(Cronograma!$B$6:$B$53,$A6,Cronograma!$Q$6:$Q$53,">="&C$5,Cronograma!$Q$6:$Q$53,"<"&EDATE(C$5,1))+COUNTIFS(Cronograma!$B$6:$B$53,$A6,Cronograma!$R$6:$R$53,">="&C$5,Cronograma!$R$6:$R$53,"<"&EDATE(C$5,1))+COUNTIFS(Cronograma!$B$6:$B$53,$A6,Cronograma!$S$6:$S$53,">="&C$5,Cronograma!$S$6:$S$53,"<"&EDATE(C$5,1)) -> 0 | D6: =COUNTIFS(Cronograma!$B$6:$B$53,$A6,Cronograma!$N$6:$N$53,">="&D$5,Cronograma!$N$6:$N$53,"<"&EDATE(D$5,1))+COUNTIFS(Cronograma!$B$6:$B$53,$A6,Cronograma!$Q$6:$Q$53,">="&D$5,Cronograma!$Q$6:$Q$53,"<"&EDATE(D$5,1))+COUNTIFS(Cronograma!$B$6:$B$53,$A6,Cronograma!$R$6:$R$53,">="&D$5,Cronograma!$R$6:$R$53,"<"&EDATE(D$5,1))+COUNTIFS(Cronograma!$B$6:$B$53,$A6,Cronograma!$S$6:$S$53,">="&D$5,Cronograma!$S$6:$S$53,"<"&EDATE(D$5,1)) -> 0 | E6: =COUNTIFS(Cronograma!$B$6:$B$53,$A6,Cronograma!$N$6:$N$53,">="&E$5,Cronograma!$N$6:$N$53,"<"&EDATE(E$5,1))+COUNTIFS(Cronograma!$B$6:$B$53,$A6,Cronograma!$Q$6:$Q$53,">="&E$5,Cronograma!$Q$6:$Q$53,"<"&EDATE(E$5,1))+COUNTIFS(Cronograma!$B$6:$B$53,$A6,Cronograma!$R$6:$R$53,">="&E$5,Cronograma!$R$6:$R$53,"<"&EDATE(E$5,1))+COUNTIFS(Cronograma!$B$6:$B$53,$A6,Cronograma!$S$6:$S$53,">="&E$5,Cronograma!$S$6:$S$53,"<"&EDATE(E$5,1)) -> 2 | F6: =COUNTIFS(Cronograma!$B$6:$B$53,$A6,Cronograma!$N$6:$N$53,">="&F$5,Cronograma!$N$6:$N$53,"<"&EDATE(F$5,1))+COUNTIFS(Cronograma!$B$6:$B$53,$A6,Cronograma!$Q$6:$Q$53,">="&F$5,Cronograma!$Q$6:$Q$53,"<"&EDATE(F$5,1))+COUNTIFS(Cronograma!$B$6:$B$53,$A6,Cronograma!$R$6:$R$53,">="&F$5,Cronograma!$R$6:$R$53,"<"&EDATE(F$5,1))+COUNTIFS(Cronograma!$B$6:$B$53,$A6,Cronograma!$S$6:$S$53,">="&F$5,Cronograma!$S$6:$S$53,"<"&EDATE(F$5,1)) -> 0 | G6: =COUNTIFS(Cronograma!$B$6:$B$53,$A6,Cronograma!$N$6:$N$53,">="&G$5,Cronograma!$N$6:$N$53,"<"&EDATE(G$5,1))+COUNTIFS(Cronograma!$B$6:$B$53,$A6,Cronograma!$Q$6:$Q$53,">="&G$5,Cronograma!$Q$6:$Q$53,"<"&EDATE(G$5,1))+COUNTIFS(Cronograma!$B$6:$B$53,$A6,Cronograma!$R$6:$R$53,">="&G$5,Cronograma!$R$6:$R$53,"<"&EDATE(G$5,1))+COUNTIFS(Cronograma!$B$6:$B$53,$A6,Cronograma!$S$6:$S$53,">="&G$5,Cronograma!$S$6:$S$53,"<"&EDATE(G$5,1)) -> 0 | H6: =COUNTIFS(Cronograma!$B$6:$B$53,$A6,Cronograma!$N$6:$N$53,">="&H$5,Cronograma!$N$6:$N$53,"<"&EDATE(H$5,1))+COUNTIFS(Cronograma!$B$6:$B$53,$A6,Cronograma!$Q$6:$Q$53,">="&H$5,Cronograma!$Q$6:$Q$53,"<"&EDATE(H$5,1))+COUNTIFS(Cronograma!$B$6:$B$53,$A6,Cronograma!$R$6:$R$53,">="&H$5,Cronograma!$R$6:$R$53,"<"&EDATE(H$5,1))+COUNTIFS(Cronograma!$B$6:$B$53,$A6,Cronograma!$S$6:$S$53,">="&H$5,Cronograma!$S$6:$S$53,"<"&EDATE(H$5,1)) -> 24 | I6: =COUNTIFS(Cronograma!$B$6:$B$53,$A6,Cronograma!$N$6:$N$53,">="&I$5,Cronograma!$N$6:$N$53,"<"&EDATE(I$5,1))+COUNTIFS(Cronograma!$B$6:$B$53,$A6,Cronograma!$Q$6:$Q$53,">="&I$5,Cronograma!$Q$6:$Q$53,"<"&EDATE(I$5,1))+COUNTIFS(Cronograma!$B$6:$B$53,$A6,Cronograma!$R$6:$R$53,">="&I$5,Cronograma!$R$6:$R$53,"<"&EDATE(I$5,1))+COUNTIFS(Cronograma!$B$6:$B$53,$A6,Cronograma!$S$6:$S$53,">="&I$5,Cronograma!$S$6:$S$53,"<"&EDATE(I$5,1)) -> 0 | ... Y6: =COUNTIFS(Cronograma!$B$6:$B$53,$A6,Cronograma!$N$6:$N$53,">="&Y$5,Cronograma!$N$6:$N$53,"<"&EDATE(Y$5,1))+COUNTIFS(Cronograma!$B$6:$B$53,$A6,Cronograma!$Q$6:$Q$53,">="&Y$5,Cronograma!$Q$6:$Q$53,"<"&EDATE(Y$5,1))+COUNTIFS(Cronograma!$B$6:$B$53,$A6,Cronograma!$R$6:$R$53,">="&Y$5,Cronograma!$R$6:$R$53,"<"&EDATE(Y$5,1))+COUNTIFS(Cronograma!$B$6:$B$53,$A6,Cronograma!$S$6:$S$53,">="&Y$5,Cronograma!$S$6:$S$53,"<"&EDATE(Y$5,1)) -> 0 | Z6: =SUM(B6:Y6) -> 104
A7: Costa - Bolívar | B7: =COUNTIFS(Cronograma!$B$6:$B$53,$A7,Cronograma!$N$6:$N$53,">="&B$5,Cronograma!$N$6:$N$53,"<"&EDATE(B$5,1))+COUNTIFS(Cronograma!$B$6:$B$53,$A7,Cronograma!$Q$6:$Q$53,">="&B$5,Cronograma!$Q$6:$Q$53,"<"&EDATE(B$5,1))+COUNTIFS(Cronograma!$B$6:$B$53,$A7,Cronograma!$R$6:$R$53,">="&B$5,Cronograma!$R$6:$R$53,"<"&EDATE(B$5,1))+COUNTIFS(Cronograma!$B$6:$B$53,$A7,Cronograma!$S$6:$S$53,">="&B$5,Cronograma!$S$6:$S$53,"<"&EDATE(B$5,1)) -> 4 | C7: =COUNTIFS(Cronograma!$B$6:$B$53,$A7,Cronograma!$N$6:$N$53,">="&C$5,Cronograma!$N$6:$N$53,"<"&EDATE(C$5,1))+COUNTIFS(Cronograma!$B$6:$B$53,$A7,Cronograma!$Q$6:$Q$53,">="&C$5,Cronograma!$Q$6:$Q$53,"<"&EDATE(C$5,1))+COUNTIFS(Cronograma!$B$6:$B$53,$A7,Cronograma!$R$6:$R$53,">="&C$5,Cronograma!$R$6:$R$53,"<"&EDATE(C$5,1))+COUNTIFS(Cronograma!$B$6:$B$53,$A7,Cronograma!$S$6:$S$53,">="&C$5,Cronograma!$S$6:$S$53,"<"&EDATE(C$5,1)) -> 0 | D7: =COUNTIFS(Cronograma!$B$6:$B$53,$A7,Cronograma!$N$6:$N$53,">="&D$5,Cronograma!$N$6:$N$53,"<"&EDATE(D$5,1))+COUNTIFS(Cronograma!$B$6:$B$53,$A7,Cronograma!$Q$6:$Q$53,">="&D$5,Cronograma!$Q$6:$Q$53,"<"&EDATE(D$5,1))+COUNTIFS(Cronograma!$B$6:$B$53,$A7,Cronograma!$R$6:$R$53,">="&D$5,Cronograma!$R$6:$R$53,"<"&EDATE(D$5,1))+COUNTIFS(Cronograma!$B$6:$B$53,$A7,Cronograma!$S$6:$S$53,">="&D$5,Cronograma!$S$6:$S$53,"<"&EDATE(D$5,1)) -> 4 | E7: =COUNTIFS(Cronograma!$B$6:$B$53,$A7,Cronograma!$N$6:$N$53,">="&E$5,Cronograma!$N$6:$N$53,"<"&EDATE(E$5,1))+COUNTIFS(Cronograma!$B$6:$B$53,$A7,Cronograma!$Q$6:$Q$53,">="&E$5,Cronograma!$Q$6:$Q$53,"<"&EDATE(E$5,1))+COUNTIFS(Cronograma!$B$6:$B$53,$A7,Cronograma!$R$6:$R$53,">="&E$5,Cronograma!$R$6:$R$53,"<"&EDATE(E$5,1))+COUNTIFS(Cronograma!$B$6:$B$53,$A7,Cronograma!$S$6:$S$53,">="&E$5,Cronograma!$S$6:$S$53,"<"&EDATE(E$5,1)) -> 0 | F7: =COUNTIFS(Cronograma!$B$6:$B$53,$A7,Cronograma!$N$6:$N$53,">="&F$5,Cronograma!$N$6:$N$53,"<"&EDATE(F$5,1))+COUNTIFS(Cronograma!$B$6:$B$53,$A7,Cronograma!$Q$6:$Q$53,">="&F$5,Cronograma!$Q$6:$Q$53,"<"&EDATE(F$5,1))+COUNTIFS(Cronograma!$B$6:$B$53,$A7,Cronograma!$R$6:$R$53,">="&F$5,Cronograma!$R$6:$R$53,"<"&EDATE(F$5,1))+COUNTIFS(Cronograma!$B$6:$B$53,$A7,Cronograma!$S$6:$S$53,">="&F$5,Cronograma!$S$6:$S$53,"<"&EDATE(F$5,1)) -> 5 | G7: =COUNTIFS(Cronograma!$B$6:$B$53,$A7,Cronograma!$N$6:$N$53,">="&G$5,Cronograma!$N$6:$N$53,"<"&EDATE(G$5,1))+COUNTIFS(Cronograma!$B$6:$B$53,$A7,Cronograma!$Q$6:$Q$53,">="&G$5,Cronograma!$Q$6:$Q$53,"<"&EDATE(G$5,1))+COUNTIFS(Cronograma!$B$6:$B$53,$A7,Cronograma!$R$6:$R$53,">="&G$5,Cronograma!$R$6:$R$53,"<"&EDATE(G$5,1))+COUNTIFS(Cronograma!$B$6:$B$53,$A7,Cronograma!$S$6:$S$53,">="&G$5,Cronograma!$S$6:$S$53,"<"&EDATE(G$5,1)) -> 4 | H7: =COUNTIFS(Cronograma!$B$6:$B$53,$A7,Cronograma!$N$6:$N$53,">="&H$5,Cronograma!$N$6:$N$53,"<"&EDATE(H$5,1))+COUNTIFS(Cronograma!$B$6:$B$53,$A7,Cronograma!$Q$6:$Q$53,">="&H$5,Cronograma!$Q$6:$Q$53,"<"&EDATE(H$5,1))+COUNTIFS(Cronograma!$B$6:$B$53,$A7,Cronograma!$R$6:$R$53,">="&H$5,Cronograma!$R$6:$R$53,"<"&EDATE(H$5,1))+COUNTIFS(Cronograma!$B$6:$B$53,$A7,Cronograma!$S$6:$S$53,">="&H$5,Cronograma!$S$6:$S$53,"<"&EDATE(H$5,1)) -> 4 | I7: =COUNTIFS(Cronograma!$B$6:$B$53,$A7,Cronograma!$N$6:$N$53,">="&I$5,Cronograma!$N$6:$N$53,"<"&EDATE(I$5,1))+COUNTIFS(Cronograma!$B$6:$B$53,$A7,Cronograma!$Q$6:$Q$53,">="&I$5,Cronograma!$Q$6:$Q$53,"<"&EDATE(I$5,1))+COUNTIFS(Cronograma!$B$6:$B$53,$A7,Cronograma!$R$6:$R$53,">="&I$5,Cronograma!$R$6:$R$53,"<"&EDATE(I$5,1))+COUNTIFS(Cronograma!$B$6:$B$53,$A7,Cronograma!$S$6:$S$53,">="&I$5,Cronograma!$S$6:$S$53,"<"&EDATE(I$5,1)) -> 0 | ... Y7: =COUNTIFS(Cronograma!$B$6:$B$53,$A7,Cronograma!$N$6:$N$53,">="&Y$5,Cronograma!$N$6:$N$53,"<"&EDATE(Y$5,1))+COUNTIFS(Cronograma!$B$6:$B$53,$A7,Cronograma!$Q$6:$Q$53,">="&Y$5,Cronograma!$Q$6:$Q$53,"<"&EDATE(Y$5,1))+COUNTIFS(Cronograma!$B$6:$B$53,$A7,Cronograma!$R$6:$R$53,">="&Y$5,Cronograma!$R$6:$R$53,"<"&EDATE(Y$5,1))+COUNTIFS(Cronograma!$B$6:$B$53,$A7,Cronograma!$S$6:$S$53,">="&Y$5,Cronograma!$S$6:$S$53,"<"&EDATE(Y$5,1)) -> 4 | Z7: =SUM(B7:Y7) -> 68
A8: Costa - Atlántico | B8: =COUNTIFS(Cronograma!$B$6:$B$53,$A8,Cronograma!$N$6:$N$53,">="&B$5,Cronograma!$N$6:$N$53,"<"&EDATE(B$5,1))+COUNTIFS(Cronograma!$B$6:$B$53,$A8,Cronograma!$Q$6:$Q$53,">="&B$5,Cronograma!$Q$6:$Q$53,"<"&EDATE(B$5,1))+COUNTIFS(Cronograma!$B$6:$B$53,$A8,Cronograma!$R$6:$R$53,">="&B$5,Cronograma!$R$6:$R$53,"<"&EDATE(B$5,1))+COUNTIFS(Cronograma!$B$6:$B$53,$A8,Cronograma!$S$6:$S$53,">="&B$5,Cronograma!$S$6:$S$53,"<"&EDATE(B$5,1)) -> 1 | C8: =COUNTIFS(Cronograma!$B$6:$B$53,$A8,Cronograma!$N$6:$N$53,">="&C$5,Cronograma!$N$6:$N$53,"<"&EDATE(C$5,1))+COUNTIFS(Cronograma!$B$6:$B$53,$A8,Cronograma!$Q$6:$Q$53,">="&C$5,Cronograma!$Q$6:$Q$53,"<"&EDATE(C$5,1))+COUNTIFS(Cronograma!$B$6:$B$53,$A8,Cronograma!$R$6:$R$53,">="&C$5,Cronograma!$R$6:$R$53,"<"&EDATE(C$5,1))+COUNTIFS(Cronograma!$B$6:$B$53,$A8,Cronograma!$S$6:$S$53,">="&C$5,Cronograma!$S$6:$S$53,"<"&EDATE(C$5,1)) -> 0 | D8: =COUNTIFS(Cronograma!$B$6:$B$53,$A8,Cronograma!$N$6:$N$53,">="&D$5,Cronograma!$N$6:$N$53,"<"&EDATE(D$5,1))+COUNTIFS(Cronograma!$B$6:$B$53,$A8,Cronograma!$Q$6:$Q$53,">="&D$5,Cronograma!$Q$6:$Q$53,"<"&EDATE(D$5,1))+COUNTIFS(Cronograma!$B$6:$B$53,$A8,Cronograma!$R$6:$R$53,">="&D$5,Cronograma!$R$6:$R$53,"<"&EDATE(D$5,1))+COUNTIFS(Cronograma!$B$6:$B$53,$A8,Cronograma!$S$6:$S$53,">="&D$5,Cronograma!$S$6:$S$53,"<"&EDATE(D$5,1)) -> 2 | E8: =COUNTIFS(Cronograma!$B$6:$B$53,$A8,Cronograma!$N$6:$N$53,">="&E$5,Cronograma!$N$6:$N$53,"<"&EDATE(E$5,1))+COUNTIFS(Cronograma!$B$6:$B$53,$A8,Cronograma!$Q$6:$Q$53,">="&E$5,Cronograma!$Q$6:$Q$53,"<"&EDATE(E$5,1))+COUNTIFS(Cronograma!$B$6:$B$53,$A8,Cronograma!$R$6:$R$53,">="&E$5,Cronograma!$R$6:$R$53,"<"&EDATE(E$5,1))+COUNTIFS(Cronograma!$B$6:$B$53,$A8,Cronograma!$S$6:$S$53,">="&E$5,Cronograma!$S$6:$S$53,"<"&EDATE(E$5,1)) -> 0 | F8: =COUNTIFS(Cronograma!$B$6:$B$53,$A8,Cronograma!$N$6:$N$53,">="&F$5,Cronograma!$N$6:$N$53,"<"&EDATE(F$5,1))+COUNTIFS(Cronograma!$B$6:$B$53,$A8,Cronograma!$Q$6:$Q$53,">="&F$5,Cronograma!$Q$6:$Q$53,"<"&EDATE(F$5,1))+COUNTIFS(Cronograma!$B$6:$B$53,$A8,Cronograma!$R$6:$R$53,">="&F$5,Cronograma!$R$6:$R$53,"<"&EDATE(F$5,1))+COUNTIFS(Cronograma!$B$6:$B$53,$A8,Cronograma!$S$6:$S$53,">="&F$5,Cronograma!$S$6:$S$53,"<"&EDATE(F$5,1)) -> 1 | G8: =COUNTIFS(Cronograma!$B$6:$B$53,$A8,Cronograma!$N$6:$N$53,">="&G$5,Cronograma!$N$6:$N$53,"<"&EDATE(G$5,1))+COUNTIFS(Cronograma!$B$6:$B$53,$A8,Cronograma!$Q$6:$Q$53,">="&G$5,Cronograma!$Q$6:$Q$53,"<"&EDATE(G$5,1))+COUNTIFS(Cronograma!$B$6:$B$53,$A8,Cronograma!$R$6:$R$53,">="&G$5,Cronograma!$R$6:$R$53,"<"&EDATE(G$5,1))+COUNTIFS(Cronograma!$B$6:$B$53,$A8,Cronograma!$S$6:$S$53,">="&G$5,Cronograma!$S$6:$S$53,"<"&EDATE(G$5,1)) -> 1 | H8: =COUNTIFS(Cronograma!$B$6:$B$53,$A8,Cronograma!$N$6:$N$53,">="&H$5,Cronograma!$N$6:$N$53,"<"&EDATE(H$5,1))+COUNTIFS(Cronograma!$B$6:$B$53,$A8,Cronograma!$Q$6:$Q$53,">="&H$5,Cronograma!$Q$6:$Q$53,"<"&EDATE(H$5,1))+COUNTIFS(Cronograma!$B$6:$B$53,$A8,Cronograma!$R$6:$R$53,">="&H$5,Cronograma!$R$6:$R$53,"<"&EDATE(H$5,1))+COUNTIFS(Cronograma!$B$6:$B$53,$A8,Cronograma!$S$6:$S$53,">="&H$5,Cronograma!$S$6:$S$53,"<"&EDATE(H$5,1)) -> 1 | I8: =COUNTIFS(Cronograma!$B$6:$B$53,$A8,Cronograma!$N$6:$N$53,">="&I$5,Cronograma!$N$6:$N$53,"<"&EDATE(I$5,1))+COUNTIFS(Cronograma!$B$6:$B$53,$A8,Cronograma!$Q$6:$Q$53,">="&I$5,Cronograma!$Q$6:$Q$53,"<"&EDATE(I$5,1))+COUNTIFS(Cronograma!$B$6:$B$53,$A8,Cronograma!$R$6:$R$53,">="&I$5,Cronograma!$R$6:$R$53,"<"&EDATE(I$5,1))+COUNTIFS(Cronograma!$B$6:$B$53,$A8,Cronograma!$S$6:$S$53,">="&I$5,Cronograma!$S$6:$S$53,"<"&EDATE(I$5,1)) -> 0 | ... Y8: =COUNTIFS(Cronograma!$B$6:$B$53,$A8,Cronograma!$N$6:$N$53,">="&Y$5,Cronograma!$N$6:$N$53,"<"&EDATE(Y$5,1))+COUNTIFS(Cronograma!$B$6:$B$53,$A8,Cronograma!$Q$6:$Q$53,">="&Y$5,Cronograma!$Q$6:$Q$53,"<"&EDATE(Y$5,1))+COUNTIFS(Cronograma!$B$6:$B$53,$A8,Cronograma!$R$6:$R$53,">="&Y$5,Cronograma!$R$6:$R$53,"<"&EDATE(Y$5,1))+COUNTIFS(Cronograma!$B$6:$B$53,$A8,Cronograma!$S$6:$S$53,">="&Y$5,Cronograma!$S$6:$S$53,"<"&EDATE(Y$5,1)) -> 1 | Z8: =SUM(B8:Y8) -> 20
A9: Total | B9: =SUM(B6:B8) -> 29 | C9: =SUM(C6:C8) -> 0 | D9: =SUM(D6:D8) -> 6 | E9: =SUM(E6:E8) -> 2 | F9: =SUM(F6:F8) -> 6 | G9: =SUM(G6:G8) -> 5 | H9: =SUM(H6:H8) -> 29 | I9: =SUM(I6:I8) -> 0 | ... Z9: =SUM(Z6:Z8) -> 192
A12: Por conjunto / zona
A13: Mes → | B13: 46296 | C13: =EDATE(B13,1) -> 46327 | D13: =EDATE(C13,1) -> 46357 | E13: =EDATE(D13,1) -> 46388 | F13: =EDATE(E13,1) -> 46419 | G13: =EDATE(F13,1) -> 46447 | H13: =EDATE(G13,1) -> 46478 | I13: =EDATE(H13,1) -> 46508 | J13: =EDATE(I13,1) -> 46539 | ... Y13: =EDATE(X13,1) -> 46997 | Z13: Total
A14: Condominio Los Abedules | B14: =COUNTIFS(Cronograma!$C$6:$C$53,$A14,Cronograma!$N$6:$N$53,">="&B$13,Cronograma!$N$6:$N$53,"<"&EDATE(B$13,1))+COUNTIFS(Cronograma!$C$6:$C$53,$A14,Cronograma!$Q$6:$Q$53,">="&B$13,Cronograma!$Q$6:$Q$53,"<"&EDATE(B$13,1))+COUNTIFS(Cronograma!$C$6:$C$53,$A14,Cronograma!$R$6:$R$53,">="&B$13,Cronograma!$R$6:$R$53,"<"&EDATE(B$13,1))+COUNTIFS(Cronograma!$C$6:$C$53,$A14,Cronograma!$S$6:$S$53,">="&B$13,Cronograma!$S$6:$S$53,"<"&EDATE(B$13,1)) -> 1 | C14: =COUNTIFS(Cronograma!$C$6:$C$53,$A14,Cronograma!$N$6:$N$53,">="&C$13,Cronograma!$N$6:$N$53,"<"&EDATE(C$13,1))+COUNTIFS(Cronograma!$C$6:$C$53,$A14,Cronograma!$Q$6:$Q$53,">="&C$13,Cronograma!$Q$6:$Q$53,"<"&EDATE(C$13,1))+COUNTIFS(Cronograma!$C$6:$C$53,$A14,Cronograma!$R$6:$R$53,">="&C$13,Cronograma!$R$6:$R$53,"<"&EDATE(C$13,1))+COUNTIFS(Cronograma!$C$6:$C$53,$A14,Cronograma!$S$6:$S$53,">="&C$13,Cronograma!$S$6:$S$53,"<"&EDATE(C$13,1)) -> 0 | D14: =COUNTIFS(Cronograma!$C$6:$C$53,$A14,Cronograma!$N$6:$N$53,">="&D$13,Cronograma!$N$6:$N$53,"<"&EDATE(D$13,1))+COUNTIFS(Cronograma!$C$6:$C$53,$A14,Cronograma!$Q$6:$Q$53,">="&D$13,Cronograma!$Q$6:$Q$53,"<"&EDATE(D$13,1))+COUNTIFS(Cronograma!$C$6:$C$53,$A14,Cronograma!$R$6:$R$53,">="&D$13,Cronograma!$R$6:$R$53,"<"&EDATE(D$13,1))+COUNTIFS(Cronograma!$C$6:$C$53,$A14,Cronograma!$S$6:$S$53,">="&D$13,Cronograma!$S$6:$S$53,"<"&EDATE(D$13,1)) -> 0 | E14: =COUNTIFS(Cronograma!$C$6:$C$53,$A14,Cronograma!$N$6:$N$53,">="&E$13,Cronograma!$N$6:$N$53,"<"&EDATE(E$13,1))+COUNTIFS(Cronograma!$C$6:$C$53,$A14,Cronograma!$Q$6:$Q$53,">="&E$13,Cronograma!$Q$6:$Q$53,"<"&EDATE(E$13,1))+COUNTIFS(Cronograma!$C$6:$C$53,$A14,Cronograma!$R$6:$R$53,">="&E$13,Cronograma!$R$6:$R$53,"<"&EDATE(E$13,1))+COUNTIFS(Cronograma!$C$6:$C$53,$A14,Cronograma!$S$6:$S$53,">="&E$13,Cronograma!$S$6:$S$53,"<"&EDATE(E$13,1)) -> 0 | F14: =COUNTIFS(Cronograma!$C$6:$C$53,$A14,Cronograma!$N$6:$N$53,">="&F$13,Cronograma!$N$6:$N$53,"<"&EDATE(F$13,1))+COUNTIFS(Cronograma!$C$6:$C$53,$A14,Cronograma!$Q$6:$Q$53,">="&F$13,Cronograma!$Q$6:$Q$53,"<"&EDATE(F$13,1))+COUNTIFS(Cronograma!$C$6:$C$53,$A14,Cronograma!$R$6:$R$53,">="&F$13,Cronograma!$R$6:$R$53,"<"&EDATE(F$13,1))+COUNTIFS(Cronograma!$C$6:$C$53,$A14,Cronograma!$S$6:$S$53,">="&F$13,Cronograma!$S$6:$S$53,"<"&EDATE(F$13,1)) -> 0 | G14: =COUNTIFS(Cronograma!$C$6:$C$53,$A14,Cronograma!$N$6:$N$53,">="&G$13,Cronograma!$N$6:$N$53,"<"&EDATE(G$13,1))+COUNTIFS(Cronograma!$C$6:$C$53,$A14,Cronograma!$Q$6:$Q$53,">="&G$13,Cronograma!$Q$6:$Q$53,"<"&EDATE(G$13,1))+COUNTIFS(Cronograma!$C$6:$C$53,$A14,Cronograma!$R$6:$R$53,">="&G$13,Cronograma!$R$6:$R$53,"<"&EDATE(G$13,1))+COUNTIFS(Cronograma!$C$6:$C$53,$A14,Cronograma!$S$6:$S$53,">="&G$13,Cronograma!$S$6:$S$53,"<"&EDATE(G$13,1)) -> 0 | H14: =COUNTIFS(Cronograma!$C$6:$C$53,$A14,Cronograma!$N$6:$N$53,">="&H$13,Cronograma!$N$6:$N$53,"<"&EDATE(H$13,1))+COUNTIFS(Cronograma!$C$6:$C$53,$A14,Cronograma!$Q$6:$Q$53,">="&H$13,Cronograma!$Q$6:$Q$53,"<"&EDATE(H$13,1))+COUNTIFS(Cronograma!$C$6:$C$53,$A14,Cronograma!$R$6:$R$53,">="&H$13,Cronograma!$R$6:$R$53,"<"&EDATE(H$13,1))+COUNTIFS(Cronograma!$C$6:$C$53,$A14,Cronograma!$S$6:$S$53,">="&H$13,Cronograma!$S$6:$S$53,"<"&EDATE(H$13,1)) -> 1 | I14: =COUNTIFS(Cronograma!$C$6:$C$53,$A14,Cronograma!$N$6:$N$53,">="&I$13,Cronograma!$N$6:$N$53,"<"&EDATE(I$13,1))+COUNTIFS(Cronograma!$C$6:$C$53,$A14,Cronograma!$Q$6:$Q$53,">="&I$13,Cronograma!$Q$6:$Q$53,"<"&EDATE(I$13,1))+COUNTIFS(Cronograma!$C$6:$C$53,$A14,Cronograma!$R$6:$R$53,">="&I$13,Cronograma!$R$6:$R$53,"<"&EDATE(I$13,1))+COUNTIFS(Cronograma!$C$6:$C$53,$A14,Cronograma!$S$6:$S$53,">="&I$13,Cronograma!$S$6:$S$53,"<"&EDATE(I$13,1)) -> 0 | ... Y14: =COUNTIFS(Cronograma!$C$6:$C$53,$A14,Cronograma!$N$6:$N$53,">="&Y$13,Cronograma!$N$6:$N$53,"<"&EDATE(Y$13,1))+COUNTIFS(Cronograma!$C$6:$C$53,$A14,Cronograma!$Q$6:$Q$53,">="&Y$13,Cronograma!$Q$6:$Q$53,"<"&EDATE(Y$13,1))+COUNTIFS(Cronograma!$C$6:$C$53,$A14,Cronograma!$R$6:$R$53,">="&Y$13,Cronograma!$R$6:$R$53,"<"&EDATE(Y$13,1))+COUNTIFS(Cronograma!$C$6:$C$53,$A14,Cronograma!$S$6:$S$53,">="&Y$13,Cronograma!$S$6:$S$53,"<"&EDATE(Y$13,1)) -> 0 | Z14: =SUM(B14:Y14) -> 4
A15: Llanos De Pance | B15: =COUNTIFS(Cronograma!$C$6:$C$53,$A15,Cronograma!$N$6:$N$53,">="&B$13,Cronograma!$N$6:$N$53,"<"&EDATE(B$13,1))+COUNTIFS(Cronograma!$C$6:$C$53,$A15,Cronograma!$Q$6:$Q$53,">="&B$13,Cronograma!$Q$6:$Q$53,"<"&EDATE(B$13,1))+COUNTIFS(Cronograma!$C$6:$C$53,$A15,Cronograma!$R$6:$R$53,">="&B$13,Cronograma!$R$6:$R$53,"<"&EDATE(B$13,1))+COUNTIFS(Cronograma!$C$6:$C$53,$A15,Cronograma!$S$6:$S$53,">="&B$13,Cronograma!$S$6:$S$53,"<"&EDATE(B$13,1)) -> 1 | C15: =COUNTIFS(Cronograma!$C$6:$C$53,$A15,Cronograma!$N$6:$N$53,">="&C$13,Cronograma!$N$6:$N$53,"<"&EDATE(C$13,1))+COUNTIFS(Cronograma!$C$6:$C$53,$A15,Cronograma!$Q$6:$Q$53,">="&C$13,Cronograma!$Q$6:$Q$53,"<"&EDATE(C$13,1))+COUNTIFS(Cronograma!$C$6:$C$53,$A15,Cronograma!$R$6:$R$53,">="&C$13,Cronograma!$R$6:$R$53,"<"&EDATE(C$13,1))+COUNTIFS(Cronograma!$C$6:$C$53,$A15,Cronograma!$S$6:$S$53,">="&C$13,Cronograma!$S$6:$S$53,"<"&EDATE(C$13,1)) -> 0 | D15: =COUNTIFS(Cronograma!$C$6:$C$53,$A15,Cronograma!$N$6:$N$53,">="&D$13,Cronograma!$N$6:$N$53,"<"&EDATE(D$13,1))+COUNTIFS(Cronograma!$C$6:$C$53,$A15,Cronograma!$Q$6:$Q$53,">="&D$13,Cronograma!$Q$6:$Q$53,"<"&EDATE(D$13,1))+COUNTIFS(Cronograma!$C$6:$C$53,$A15,Cronograma!$R$6:$R$53,">="&D$13,Cronograma!$R$6:$R$53,"<"&EDATE(D$13,1))+COUNTIFS(Cronograma!$C$6:$C$53,$A15,Cronograma!$S$6:$S$53,">="&D$13,Cronograma!$S$6:$S$53,"<"&EDATE(D$13,1)) -> 0 | E15: =COUNTIFS(Cronograma!$C$6:$C$53,$A15,Cronograma!$N$6:$N$53,">="&E$13,Cronograma!$N$6:$N$53,"<"&EDATE(E$13,1))+COUNTIFS(Cronograma!$C$6:$C$53,$A15,Cronograma!$Q$6:$Q$53,">="&E$13,Cronograma!$Q$6:$Q$53,"<"&EDATE(E$13,1))+COUNTIFS(Cronograma!$C$6:$C$53,$A15,Cronograma!$R$6:$R$53,">="&E$13,Cronograma!$R$6:$R$53,"<"&EDATE(E$13,1))+COUNTIFS(Cronograma!$C$6:$C$53,$A15,Cronograma!$S$6:$S$53,">="&E$13,Cronograma!$S$6:$S$53,"<"&EDATE(E$13,1)) -> 0 | F15: =COUNTIFS(Cronograma!$C$6:$C$53,$A15,Cronograma!$N$6:$N$53,">="&F$13,Cronograma!$N$6:$N$53,"<"&EDATE(F$13,1))+COUNTIFS(Cronograma!$C$6:$C$53,$A15,Cronograma!$Q$6:$Q$53,">="&F$13,Cronograma!$Q$6:$Q$53,"<"&EDATE(F$13,1))+COUNTIFS(Cronograma!$C$6:$C$53,$A15,Cronograma!$R$6:$R$53,">="&F$13,Cronograma!$R$6:$R$53,"<"&EDATE(F$13,1))+COUNTIFS(Cronograma!$C$6:$C$53,$A15,Cronograma!$S$6:$S$53,">="&F$13,Cronograma!$S$6:$S$53,"<"&EDATE(F$13,1)) -> 0 | G15: =COUNTIFS(Cronograma!$C$6:$C$53,$A15,Cronograma!$N$6:$N$53,">="&G$13,Cronograma!$N$6:$N$53,"<"&EDATE(G$13,1))+COUNTIFS(Cronograma!$C$6:$C$53,$A15,Cronograma!$Q$6:$Q$53,">="&G$13,Cronograma!$Q$6:$Q$53,"<"&EDATE(G$13,1))+COUNTIFS(Cronograma!$C$6:$C$53,$A15,Cronograma!$R$6:$R$53,">="&G$13,Cronograma!$R$6:$R$53,"<"&EDATE(G$13,1))+COUNTIFS(Cronograma!$C$6:$C$53,$A15,Cronograma!$S$6:$S$53,">="&G$13,Cronograma!$S$6:$S$53,"<"&EDATE(G$13,1)) -> 0 | H15: =COUNTIFS(Cronograma!$C$6:$C$53,$A15,Cronograma!$N$6:$N$53,">="&H$13,Cronograma!$N$6:$N$53,"<"&EDATE(H$13,1))+COUNTIFS(Cronograma!$C$6:$C$53,$A15,Cronograma!$Q$6:$Q$53,">="&H$13,Cronograma!$Q$6:$Q$53,"<"&EDATE(H$13,1))+COUNTIFS(Cronograma!$C$6:$C$53,$A15,Cronograma!$R$6:$R$53,">="&H$13,Cronograma!$R$6:$R$53,"<"&EDATE(H$13,1))+COUNTIFS(Cronograma!$C$6:$C$53,$A15,Cronograma!$S$6:$S$53,">="&H$13,Cronograma!$S$6:$S$53,"<"&EDATE(H$13,1)) -> 1 | I15: =COUNTIFS(Cronograma!$C$6:$C$53,$A15,Cronograma!$N$6:$N$53,">="&I$13,Cronograma!$N$6:$N$53,"<"&EDATE(I$13,1))+COUNTIFS(Cronograma!$C$6:$C$53,$A15,Cronograma!$Q$6:$Q$53,">="&I$13,Cronograma!$Q$6:$Q$53,"<"&EDATE(I$13,1))+COUNTIFS(Cronograma!$C$6:$C$53,$A15,Cronograma!$R$6:$R$53,">="&I$13,Cronograma!$R$6:$R$53,"<"&EDATE(I$13,1))+COUNTIFS(Cronograma!$C$6:$C$53,$A15,Cronograma!$S$6:$S$53,">="&I$13,Cronograma!$S$6:$S$53,"<"&EDATE(I$13,1)) -> 0 | ... Y15: =COUNTIFS(Cronograma!$C$6:$C$53,$A15,Cronograma!$N$6:$N$53,">="&Y$13,Cronograma!$N$6:$N$53,"<"&EDATE(Y$13,1))+COUNTIFS(Cronograma!$C$6:$C$53,$A15,Cronograma!$Q$6:$Q$53,">="&Y$13,Cronograma!$Q$6:$Q$53,"<"&EDATE(Y$13,1))+COUNTIFS(Cronograma!$C$6:$C$53,$A15,Cronograma!$R$6:$R$53,">="&Y$13,Cronograma!$R$6:$R$53,"<"&EDATE(Y$13,1))+COUNTIFS(Cronograma!$C$6:$C$53,$A15,Cronograma!$S$6:$S$53,">="&Y$13,Cronograma!$S$6:$S$53,"<"&EDATE(Y$13,1)) -> 0 | Z15: =SUM(B15:Y15) -> 4
A16: Pance Campestre | B16: =COUNTIFS(Cronograma!$C$6:$C$53,$A16,Cronograma!$N$6:$N$53,">="&B$13,Cronograma!$N$6:$N$53,"<"&EDATE(B$13,1))+COUNTIFS(Cronograma!$C$6:$C$53,$A16,Cronograma!$Q$6:$Q$53,">="&B$13,Cronograma!$Q$6:$Q$53,"<"&EDATE(B$13,1))+COUNTIFS(Cronograma!$C$6:$C$53,$A16,Cronograma!$R$6:$R$53,">="&B$13,Cronograma!$R$6:$R$53,"<"&EDATE(B$13,1))+COUNTIFS(Cronograma!$C$6:$C$53,$A16,Cronograma!$S$6:$S$53,">="&B$13,Cronograma!$S$6:$S$53,"<"&EDATE(B$13,1)) -> 0 | C16: =COUNTIFS(Cronograma!$C$6:$C$53,$A16,Cronograma!$N$6:$N$53,">="&C$13,Cronograma!$N$6:$N$53,"<"&EDATE(C$13,1))+COUNTIFS(Cronograma!$C$6:$C$53,$A16,Cronograma!$Q$6:$Q$53,">="&C$13,Cronograma!$Q$6:$Q$53,"<"&EDATE(C$13,1))+COUNTIFS(Cronograma!$C$6:$C$53,$A16,Cronograma!$R$6:$R$53,">="&C$13,Cronograma!$R$6:$R$53,"<"&EDATE(C$13,1))+COUNTIFS(Cronograma!$C$6:$C$53,$A16,Cronograma!$S$6:$S$53,">="&C$13,Cronograma!$S$6:$S$53,"<"&EDATE(C$13,1)) -> 0 | D16: =COUNTIFS(Cronograma!$C$6:$C$53,$A16,Cronograma!$N$6:$N$53,">="&D$13,Cronograma!$N$6:$N$53,"<"&EDATE(D$13,1))+COUNTIFS(Cronograma!$C$6:$C$53,$A16,Cronograma!$Q$6:$Q$53,">="&D$13,Cronograma!$Q$6:$Q$53,"<"&EDATE(D$13,1))+COUNTIFS(Cronograma!$C$6:$C$53,$A16,Cronograma!$R$6:$R$53,">="&D$13,Cronograma!$R$6:$R$53,"<"&EDATE(D$13,1))+COUNTIFS(Cronograma!$C$6:$C$53,$A16,Cronograma!$S$6:$S$53,">="&D$13,Cronograma!$S$6:$S$53,"<"&EDATE(D$13,1)) -> 0 | E16: =COUNTIFS(Cronograma!$C$6:$C$53,$A16,Cronograma!$N$6:$N$53,">="&E$13,Cronograma!$N$6:$N$53,"<"&EDATE(E$13,1))+COUNTIFS(Cronograma!$C$6:$C$53,$A16,Cronograma!$Q$6:$Q$53,">="&E$13,Cronograma!$Q$6:$Q$53,"<"&EDATE(E$13,1))+COUNTIFS(Cronograma!$C$6:$C$53,$A16,Cronograma!$R$6:$R$53,">="&E$13,Cronograma!$R$6:$R$53,"<"&EDATE(E$13,1))+COUNTIFS(Cronograma!$C$6:$C$53,$A16,Cronograma!$S$6:$S$53,">="&E$13,Cronograma!$S$6:$S$53,"<"&EDATE(E$13,1)) -> 1 | F16: =COUNTIFS(Cronograma!$C$6:$C$53,$A16,Cronograma!$N$6:$N$53,">="&F$13,Cronograma!$N$6:$N$53,"<"&EDATE(F$13,1))+COUNTIFS(Cronograma!$C$6:$C$53,$A16,Cronograma!$Q$6:$Q$53,">="&F$13,Cronograma!$Q$6:$Q$53,"<"&EDATE(F$13,1))+COUNTIFS(Cronograma!$C$6:$C$53,$A16,Cronograma!$R$6:$R$53,">="&F$13,Cronograma!$R$6:$R$53,"<"&EDATE(F$13,1))+COUNTIFS(Cronograma!$C$6:$C$53,$A16,Cronograma!$S$6:$S$53,">="&F$13,Cronograma!$S$6:$S$53,"<"&EDATE(F$13,1)) -> 0 | G16: =COUNTIFS(Cronograma!$C$6:$C$53,$A16,Cronograma!$N$6:$N$53,">="&G$13,Cronograma!$N$6:$N$53,"<"&EDATE(G$13,1))+COUNTIFS(Cronograma!$C$6:$C$53,$A16,Cronograma!$Q$6:$Q$53,">="&G$13,Cronograma!$Q$6:$Q$53,"<"&EDATE(G$13,1))+COUNTIFS(Cronograma!$C$6:$C$53,$A16,Cronograma!$R$6:$R$53,">="&G$13,Cronograma!$R$6:$R$53,"<"&EDATE(G$13,1))+COUNTIFS(Cronograma!$C$6:$C$53,$A16,Cronograma!$S$6:$S$53,">="&G$13,Cronograma!$S$6:$S$53,"<"&EDATE(G$13,1)) -> 0 | H16: =COUNTIFS(Cronograma!$C$6:$C$53,$A16,Cronograma!$N$6:$N$53,">="&H$13,Cronograma!$N$6:$N$53,"<"&EDATE(H$13,1))+COUNTIFS(Cronograma!$C$6:$C$53,$A16,Cronograma!$Q$6:$Q$53,">="&H$13,Cronograma!$Q$6:$Q$53,"<"&EDATE(H$13,1))+COUNTIFS(Cronograma!$C$6:$C$53,$A16,Cronograma!$R$6:$R$53,">="&H$13,Cronograma!$R$6:$R$53,"<"&EDATE(H$13,1))+COUNTIFS(Cronograma!$C$6:$C$53,$A16,Cronograma!$S$6:$S$53,">="&H$13,Cronograma!$S$6:$S$53,"<"&EDATE(H$13,1)) -> 0 | I16: =COUNTIFS(Cronograma!$C$6:$C$53,$A16,Cronograma!$N$6:$N$53,">="&I$13,Cronograma!$N$6:$N$53,"<"&EDATE(I$13,1))+COUNTIFS(Cronograma!$C$6:$C$53,$A16,Cronograma!$Q$6:$Q$53,">="&I$13,Cronograma!$Q$6:$Q$53,"<"&EDATE(I$13,1))+COUNTIFS(Cronograma!$C$6:$C$53,$A16,Cronograma!$R$6:$R$53,">="&I$13,Cronograma!$R$6:$R$53,"<"&EDATE(I$13,1))+COUNTIFS(Cronograma!$C$6:$C$53,$A16,Cronograma!$S$6:$S$53,">="&I$13,Cronograma!$S$6:$S$53,"<"&EDATE(I$13,1)) -> 0 | ... Y16: =COUNTIFS(Cronograma!$C$6:$C$53,$A16,Cronograma!$N$6:$N$53,">="&Y$13,Cronograma!$N$6:$N$53,"<"&EDATE(Y$13,1))+COUNTIFS(Cronograma!$C$6:$C$53,$A16,Cronograma!$Q$6:$Q$53,">="&Y$13,Cronograma!$Q$6:$Q$53,"<"&EDATE(Y$13,1))+COUNTIFS(Cronograma!$C$6:$C$53,$A16,Cronograma!$R$6:$R$53,">="&Y$13,Cronograma!$R$6:$R$53,"<"&EDATE(Y$13,1))+COUNTIFS(Cronograma!$C$6:$C$53,$A16,Cronograma!$S$6:$S$53,">="&Y$13,Cronograma!$S$6:$S$53,"<"&EDATE(Y$13,1)) -> 0 | Z16: =SUM(B16:Y16) -> 4
